[32m[I 2024-04-16 18:41:08,675][39m A new study created in memory with name: no-name-297b97fe-aad8-4936-8543-a414169f50ee
[33m[W 2024-04-16 18:41:08,701][39m Trial 0 failed with parameters: {} because of the following error: ValueError('wandb.log must be passed a dictionary').
Traceback (most recent call last):
  File "/home/anushka/Desktop/take_home/task_1/mlops_env/.pixi/envs/default/lib/python3.12/site-packages/optuna/study/_optimize.py", line 196, in _run_trial
    value_or_values = func(trial)
                      ^^^^^^^^^^^
  File "/home/anushka/Desktop/take_home/task_1/mlops_env/mlops_task.py", line 123, in objective
    sanity_checks(digits)
  File "/home/anushka/Desktop/take_home/task_1/mlops_env/mlops_task.py", line 82, in sanity_checks
    wandb.log("Image Data Shape", digits.data.shape)
  File "/home/anushka/Desktop/take_home/task_1/mlops_env/.pixi/envs/default/lib/python3.12/site-packages/wandb/sdk/wandb_run.py", line 420, in wrapper
    return func(self, *args, **kwargs)
           ^^^^^^^^^^^^^^^^^^^^^^^^^^^
  File "/home/anushka/Desktop/take_home/task_1/mlops_env/.pixi/envs/default/lib/python3.12/site-packages/wandb/sdk/wandb_run.py", line 371, in wrapper_fn
    return func(self, *args, **kwargs)
           ^^^^^^^^^^^^^^^^^^^^^^^^^^^
  File "/home/anushka/Desktop/take_home/task_1/mlops_env/.pixi/envs/default/lib/python3.12/site-packages/wandb/sdk/wandb_run.py", line 361, in wrapper
    return func(self, *args, **kwargs)
           ^^^^^^^^^^^^^^^^^^^^^^^^^^^
  File "/home/anushka/Desktop/take_home/task_1/mlops_env/.pixi/envs/default/lib/python3.12/site-packages/wandb/sdk/wandb_run.py", line 1838, in log
    self._log(data=data, step=step, commit=commit)
  File "/home/anushka/Desktop/take_home/task_1/mlops_env/.pixi/envs/default/lib/python3.12/site-packages/wandb/sdk/wandb_run.py", line 1597, in _log
    raise ValueError("wandb.log must be passed a dictionary")
ValueError: wandb.log must be passed a dictionary
[33m[W 2024-04-16 18:41:08,704][39m Trial 0 failed with value None.
Traceback (most recent call last):
  File "/home/anushka/Desktop/take_home/task_1/mlops_env/mlops_task.py", line 170, in <module>
    main()
  File "/home/anushka/Desktop/take_home/task_1/mlops_env/mlops_task.py", line 162, in main
    study.optimize(objective, n_trials=5)
  File "/home/anushka/Desktop/take_home/task_1/mlops_env/.pixi/envs/default/lib/python3.12/site-packages/optuna/study/study.py", line 451, in optimize
    _optimize(
  File "/home/anushka/Desktop/take_home/task_1/mlops_env/.pixi/envs/default/lib/python3.12/site-packages/optuna/study/_optimize.py", line 62, in _optimize
    _optimize_sequential(
  File "/home/anushka/Desktop/take_home/task_1/mlops_env/.pixi/envs/default/lib/python3.12/site-packages/optuna/study/_optimize.py", line 159, in _optimize_sequential
    frozen_trial = _run_trial(study, func, catch)
                   ^^^^^^^^^^^^^^^^^^^^^^^^^^^^^^
  File "/home/anushka/Desktop/take_home/task_1/mlops_env/.pixi/envs/default/lib/python3.12/site-packages/optuna/study/_optimize.py", line 247, in _run_trial
    raise func_err
  File "/home/anushka/Desktop/take_home/task_1/mlops_env/.pixi/envs/default/lib/python3.12/site-packages/optuna/study/_optimize.py", line 196, in _run_trial
    value_or_values = func(trial)
                      ^^^^^^^^^^^
  File "/home/anushka/Desktop/take_home/task_1/mlops_env/mlops_task.py", line 123, in objective
    sanity_checks(digits)
  File "/home/anushka/Desktop/take_home/task_1/mlops_env/mlops_task.py", line 82, in sanity_checks
    wandb.log("Image Data Shape", digits.data.shape)
  File "/home/anushka/Desktop/take_home/task_1/mlops_env/.pixi/envs/default/lib/python3.12/site-packages/wandb/sdk/wandb_run.py", line 420, in wrapper
    return func(self, *args, **kwargs)
           ^^^^^^^^^^^^^^^^^^^^^^^^^^^
  File "/home/anushka/Desktop/take_home/task_1/mlops_env/.pixi/envs/default/lib/python3.12/site-packages/wandb/sdk/wandb_run.py", line 371, in wrapper_fn
    return func(self, *args, **kwargs)
           ^^^^^^^^^^^^^^^^^^^^^^^^^^^
  File "/home/anushka/Desktop/take_home/task_1/mlops_env/.pixi/envs/default/lib/python3.12/site-packages/wandb/sdk/wandb_run.py", line 361, in wrapper
    return func(self, *args, **kwargs)
           ^^^^^^^^^^^^^^^^^^^^^^^^^^^
  File "/home/anushka/Desktop/take_home/task_1/mlops_env/.pixi/envs/default/lib/python3.12/site-packages/wandb/sdk/wandb_run.py", line 1838, in log
    self._log(data=data, step=step, commit=commit)
  File "/home/anushka/Desktop/take_home/task_1/mlops_env/.pixi/envs/default/lib/python3.12/site-packages/wandb/sdk/wandb_run.py", line 1597, in _log
    raise ValueError("wandb.log must be passed a dictionary")
ValueError: wandb.log must be passed a dictionary