[32m[I 2024-04-19 19:15:31,925][39m A new study created in memory with name: no-name-0f9fe976-1f3a-421f-96f3-7ffff2b71237
[33m[W 2024-04-19 19:15:32,344][39m Trial 0 failed with parameters: {'penality': 'l2', 'solver_l2': 'liblinear', 'inverse_of_regularization_strength': 0.3278019202202348, 'fit_intercept': True, 'intercept_scaling': 0.7986578568789953} because of the following error: TypeError('Invalid shape (64,) for image data').
Traceback (most recent call last):
  File "/home/anushka/Desktop/take_home/task_1/mlops_env/.pixi/envs/default/lib/python3.12/site-packages/optuna/study/_optimize.py", line 196, in _run_trial
    value_or_values = func(trial)
                      ^^^^^^^^^^^
  File "/home/anushka/Desktop/take_home/task_1/mlops_env/mlops_task.py", line 153, in objective
    visualize_test(x_test, y_test, predictions)
  File "/home/anushka/Desktop/take_home/task_1/mlops_env/mlops_task.py", line 99, in visualize_test
    table.add_data(plt.imshow(image_array, cmap=plt.cm.gray), label, prediction)
                   ^^^^^^^^^^^^^^^^^^^^^^^^^^^^^^^^^^^^^^^^^
  File "/home/anushka/Desktop/take_home/task_1/mlops_env/.pixi/envs/default/lib/python3.12/site-packages/matplotlib/pyplot.py", line 3358, in imshow
    __ret = gca().imshow(
            ^^^^^^^^^^^^^
  File "/home/anushka/Desktop/take_home/task_1/mlops_env/.pixi/envs/default/lib/python3.12/site-packages/matplotlib/__init__.py", line 1465, in inner
    return func(ax, *map(sanitize_sequence, args), **kwargs)
           ^^^^^^^^^^^^^^^^^^^^^^^^^^^^^^^^^^^^^^^^^^^^^^^^^
  File "/home/anushka/Desktop/take_home/task_1/mlops_env/.pixi/envs/default/lib/python3.12/site-packages/matplotlib/axes/_axes.py", line 5759, in imshow
    im.set_data(X)
  File "/home/anushka/Desktop/take_home/task_1/mlops_env/.pixi/envs/default/lib/python3.12/site-packages/matplotlib/image.py", line 723, in set_data
    self._A = self._normalize_image_array(A)
              ^^^^^^^^^^^^^^^^^^^^^^^^^^^^^^
  File "/home/anushka/Desktop/take_home/task_1/mlops_env/.pixi/envs/default/lib/python3.12/site-packages/matplotlib/image.py", line 693, in _normalize_image_array
    raise TypeError(f"Invalid shape {A.shape} for image data")
TypeError: Invalid shape (64,) for image data
[33m[W 2024-04-19 19:15:32,356][39m Trial 0 failed with value None.
Traceback (most recent call last):
  File "/home/anushka/Desktop/take_home/task_1/mlops_env/mlops_task.py", line 174, in <module>
    main()
  File "/home/anushka/Desktop/take_home/task_1/mlops_env/mlops_task.py", line 166, in main
    study.optimize(objective, n_trials=5)
  File "/home/anushka/Desktop/take_home/task_1/mlops_env/.pixi/envs/default/lib/python3.12/site-packages/optuna/study/study.py", line 451, in optimize
    _optimize(
  File "/home/anushka/Desktop/take_home/task_1/mlops_env/.pixi/envs/default/lib/python3.12/site-packages/optuna/study/_optimize.py", line 62, in _optimize
    _optimize_sequential(
  File "/home/anushka/Desktop/take_home/task_1/mlops_env/.pixi/envs/default/lib/python3.12/site-packages/optuna/study/_optimize.py", line 159, in _optimize_sequential
    frozen_trial = _run_trial(study, func, catch)
                   ^^^^^^^^^^^^^^^^^^^^^^^^^^^^^^
  File "/home/anushka/Desktop/take_home/task_1/mlops_env/.pixi/envs/default/lib/python3.12/site-packages/optuna/study/_optimize.py", line 247, in _run_trial
    raise func_err
  File "/home/anushka/Desktop/take_home/task_1/mlops_env/.pixi/envs/default/lib/python3.12/site-packages/optuna/study/_optimize.py", line 196, in _run_trial
    value_or_values = func(trial)
                      ^^^^^^^^^^^
  File "/home/anushka/Desktop/take_home/task_1/mlops_env/mlops_task.py", line 153, in objective
    visualize_test(x_test, y_test, predictions)
  File "/home/anushka/Desktop/take_home/task_1/mlops_env/mlops_task.py", line 99, in visualize_test
    table.add_data(plt.imshow(image_array, cmap=plt.cm.gray), label, prediction)
                   ^^^^^^^^^^^^^^^^^^^^^^^^^^^^^^^^^^^^^^^^^
  File "/home/anushka/Desktop/take_home/task_1/mlops_env/.pixi/envs/default/lib/python3.12/site-packages/matplotlib/pyplot.py", line 3358, in imshow
    __ret = gca().imshow(
            ^^^^^^^^^^^^^
  File "/home/anushka/Desktop/take_home/task_1/mlops_env/.pixi/envs/default/lib/python3.12/site-packages/matplotlib/__init__.py", line 1465, in inner
    return func(ax, *map(sanitize_sequence, args), **kwargs)
           ^^^^^^^^^^^^^^^^^^^^^^^^^^^^^^^^^^^^^^^^^^^^^^^^^
  File "/home/anushka/Desktop/take_home/task_1/mlops_env/.pixi/envs/default/lib/python3.12/site-packages/matplotlib/axes/_axes.py", line 5759, in imshow
    im.set_data(X)
  File "/home/anushka/Desktop/take_home/task_1/mlops_env/.pixi/envs/default/lib/python3.12/site-packages/matplotlib/image.py", line 723, in set_data
    self._A = self._normalize_image_array(A)
              ^^^^^^^^^^^^^^^^^^^^^^^^^^^^^^
  File "/home/anushka/Desktop/take_home/task_1/mlops_env/.pixi/envs/default/lib/python3.12/site-packages/matplotlib/image.py", line 693, in _normalize_image_array
    raise TypeError(f"Invalid shape {A.shape} for image data")
TypeError: Invalid shape (64,) for image data