2024-04-19 18:27:18,152 INFO    StreamThr :60959 [internal.py:wandb_internal():86] W&B internal server running at pid: 60959, started at: 2024-04-19 18:27:18.152284
2024-04-19 18:27:18,153 DEBUG   HandlerThread:60959 [handler.py:handle_request():146] handle_request: status
2024-04-19 18:27:18,155 INFO    WriterThread:60959 [datastore.py:open_for_write():87] open: /home/anushka/Desktop/take_home/task_1/mlops_env/wandb/run-20240419_182718-4zbcv803/run-4zbcv803.wandb
2024-04-19 18:27:18,155 DEBUG   SenderThread:60959 [sender.py:send():379] send: header
2024-04-19 18:27:18,155 DEBUG   SenderThread:60959 [sender.py:send():379] send: run
2024-04-19 18:27:23,167 DEBUG   HandlerThread:60959 [handler.py:handle_request():146] handle_request: keepalive
2024-04-19 18:27:28,167 DEBUG   HandlerThread:60959 [handler.py:handle_request():146] handle_request: keepalive
2024-04-19 18:27:31,017 INFO    SenderThread:60959 [retry.py:__call__():172] Retry attempt failed:
Traceback (most recent call last):
  File "/home/anushka/Desktop/take_home/task_1/mlops_env/.pixi/envs/default/lib/python3.12/site-packages/urllib3/connectionpool.py", line 467, in _make_request
    self._validate_conn(conn)
  File "/home/anushka/Desktop/take_home/task_1/mlops_env/.pixi/envs/default/lib/python3.12/site-packages/urllib3/connectionpool.py", line 1099, in _validate_conn
    conn.connect()
  File "/home/anushka/Desktop/take_home/task_1/mlops_env/.pixi/envs/default/lib/python3.12/site-packages/urllib3/connection.py", line 653, in connect
    sock_and_verified = _ssl_wrap_socket_and_match_hostname(
                        ^^^^^^^^^^^^^^^^^^^^^^^^^^^^^^^^^^^^
  File "/home/anushka/Desktop/take_home/task_1/mlops_env/.pixi/envs/default/lib/python3.12/site-packages/urllib3/connection.py", line 806, in _ssl_wrap_socket_and_match_hostname
    ssl_sock = ssl_wrap_socket(
               ^^^^^^^^^^^^^^^^
  File "/home/anushka/Desktop/take_home/task_1/mlops_env/.pixi/envs/default/lib/python3.12/site-packages/urllib3/util/ssl_.py", line 465, in ssl_wrap_socket
    ssl_sock = _ssl_wrap_socket_impl(sock, context, tls_in_tls, server_hostname)
               ^^^^^^^^^^^^^^^^^^^^^^^^^^^^^^^^^^^^^^^^^^^^^^^^^^^^^^^^^^^^^^^^^
  File "/home/anushka/Desktop/take_home/task_1/mlops_env/.pixi/envs/default/lib/python3.12/site-packages/urllib3/util/ssl_.py", line 509, in _ssl_wrap_socket_impl
    return ssl_context.wrap_socket(sock, server_hostname=server_hostname)
           ^^^^^^^^^^^^^^^^^^^^^^^^^^^^^^^^^^^^^^^^^^^^^^^^^^^^^^^^^^^^^^
  File "/home/anushka/Desktop/take_home/task_1/mlops_env/.pixi/envs/default/lib/python3.12/ssl.py", line 455, in wrap_socket
    return self.sslsocket_class._create(
           ^^^^^^^^^^^^^^^^^^^^^^^^^^^^^
  File "/home/anushka/Desktop/take_home/task_1/mlops_env/.pixi/envs/default/lib/python3.12/ssl.py", line 1042, in _create
    self.do_handshake()
  File "/home/anushka/Desktop/take_home/task_1/mlops_env/.pixi/envs/default/lib/python3.12/ssl.py", line 1320, in do_handshake
    self._sslobj.do_handshake()
ssl.SSLEOFError: [SSL: UNEXPECTED_EOF_WHILE_READING] EOF occurred in violation of protocol (_ssl.c:1000)

During handling of the above exception, another exception occurred:

Traceback (most recent call last):
  File "/home/anushka/Desktop/take_home/task_1/mlops_env/.pixi/envs/default/lib/python3.12/site-packages/urllib3/connectionpool.py", line 793, in urlopen
    response = self._make_request(
               ^^^^^^^^^^^^^^^^^^^
  File "/home/anushka/Desktop/take_home/task_1/mlops_env/.pixi/envs/default/lib/python3.12/site-packages/urllib3/connectionpool.py", line 491, in _make_request
    raise new_e
urllib3.exceptions.SSLError: [SSL: UNEXPECTED_EOF_WHILE_READING] EOF occurred in violation of protocol (_ssl.c:1000)

The above exception was the direct cause of the following exception:

Traceback (most recent call last):
  File "/home/anushka/Desktop/take_home/task_1/mlops_env/.pixi/envs/default/lib/python3.12/site-packages/requests/adapters.py", line 486, in send
    resp = conn.urlopen(
           ^^^^^^^^^^^^^
  File "/home/anushka/Desktop/take_home/task_1/mlops_env/.pixi/envs/default/lib/python3.12/site-packages/urllib3/connectionpool.py", line 847, in urlopen
    retries = retries.increment(
              ^^^^^^^^^^^^^^^^^^
  File "/home/anushka/Desktop/take_home/task_1/mlops_env/.pixi/envs/default/lib/python3.12/site-packages/urllib3/util/retry.py", line 515, in increment
    raise MaxRetryError(_pool, url, reason) from reason  # type: ignore[arg-type]
    ^^^^^^^^^^^^^^^^^^^^^^^^^^^^^^^^^^^^^^^^^^^^^^^^^^^
urllib3.exceptions.MaxRetryError: HTTPSConnectionPool(host='api.wandb.ai', port=443): Max retries exceeded with url: /graphql (Caused by SSLError(SSLEOFError(8, '[SSL: UNEXPECTED_EOF_WHILE_READING] EOF occurred in violation of protocol (_ssl.c:1000)')))

During handling of the above exception, another exception occurred:

Traceback (most recent call last):
  File "/home/anushka/Desktop/take_home/task_1/mlops_env/.pixi/envs/default/lib/python3.12/site-packages/wandb/sdk/lib/retry.py", line 131, in __call__
    result = self._call_fn(*args, **kwargs)
             ^^^^^^^^^^^^^^^^^^^^^^^^^^^^^^
  File "/home/anushka/Desktop/take_home/task_1/mlops_env/.pixi/envs/default/lib/python3.12/site-packages/wandb/sdk/internal/internal_api.py", line 369, in execute
    return self.client.execute(*args, **kwargs)  # type: ignore
           ^^^^^^^^^^^^^^^^^^^^^^^^^^^^^^^^^^^^
  File "/home/anushka/Desktop/take_home/task_1/mlops_env/.pixi/envs/default/lib/python3.12/site-packages/wandb/vendor/gql-0.2.0/wandb_gql/client.py", line 52, in execute
    result = self._get_result(document, *args, **kwargs)
             ^^^^^^^^^^^^^^^^^^^^^^^^^^^^^^^^^^^^^^^^^^^
  File "/home/anushka/Desktop/take_home/task_1/mlops_env/.pixi/envs/default/lib/python3.12/site-packages/wandb/vendor/gql-0.2.0/wandb_gql/client.py", line 60, in _get_result
    return self.transport.execute(document, *args, **kwargs)
           ^^^^^^^^^^^^^^^^^^^^^^^^^^^^^^^^^^^^^^^^^^^^^^^^^
  File "/home/anushka/Desktop/take_home/task_1/mlops_env/.pixi/envs/default/lib/python3.12/site-packages/wandb/sdk/lib/gql_request.py", line 58, in execute
    request = self.session.post(self.url, **post_args)
              ^^^^^^^^^^^^^^^^^^^^^^^^^^^^^^^^^^^^^^^^
  File "/home/anushka/Desktop/take_home/task_1/mlops_env/.pixi/envs/default/lib/python3.12/site-packages/requests/sessions.py", line 637, in post
    return self.request("POST", url, data=data, json=json, **kwargs)
           ^^^^^^^^^^^^^^^^^^^^^^^^^^^^^^^^^^^^^^^^^^^^^^^^^^^^^^^^^
  File "/home/anushka/Desktop/take_home/task_1/mlops_env/.pixi/envs/default/lib/python3.12/site-packages/requests/sessions.py", line 589, in request
    resp = self.send(prep, **send_kwargs)
           ^^^^^^^^^^^^^^^^^^^^^^^^^^^^^^
  File "/home/anushka/Desktop/take_home/task_1/mlops_env/.pixi/envs/default/lib/python3.12/site-packages/requests/sessions.py", line 703, in send
    r = adapter.send(request, **kwargs)
        ^^^^^^^^^^^^^^^^^^^^^^^^^^^^^^^
  File "/home/anushka/Desktop/take_home/task_1/mlops_env/.pixi/envs/default/lib/python3.12/site-packages/requests/adapters.py", line 517, in send
    raise SSLError(e, request=request)
requests.exceptions.SSLError: HTTPSConnectionPool(host='api.wandb.ai', port=443): Max retries exceeded with url: /graphql (Caused by SSLError(SSLEOFError(8, '[SSL: UNEXPECTED_EOF_WHILE_READING] EOF occurred in violation of protocol (_ssl.c:1000)')))
2024-04-19 18:27:33,169 DEBUG   HandlerThread:60959 [handler.py:handle_request():146] handle_request: keepalive
2024-04-19 18:27:38,170 DEBUG   HandlerThread:60959 [handler.py:handle_request():146] handle_request: keepalive
2024-04-19 18:27:43,171 DEBUG   HandlerThread:60959 [handler.py:handle_request():146] handle_request: keepalive
2024-04-19 18:27:48,172 DEBUG   HandlerThread:60959 [handler.py:handle_request():146] handle_request: keepalive
2024-04-19 18:27:53,173 DEBUG   HandlerThread:60959 [handler.py:handle_request():146] handle_request: keepalive
2024-04-19 18:27:58,173 DEBUG   HandlerThread:60959 [handler.py:handle_request():146] handle_request: keepalive
2024-04-19 18:28:03,175 DEBUG   HandlerThread:60959 [handler.py:handle_request():146] handle_request: keepalive
2024-04-19 18:28:08,176 DEBUG   HandlerThread:60959 [handler.py:handle_request():146] handle_request: keepalive
2024-04-19 18:28:13,177 DEBUG   HandlerThread:60959 [handler.py:handle_request():146] handle_request: keepalive
2024-04-19 18:28:18,179 DEBUG   HandlerThread:60959 [handler.py:handle_request():146] handle_request: keepalive
2024-04-19 18:28:23,180 DEBUG   HandlerThread:60959 [handler.py:handle_request():146] handle_request: keepalive
2024-04-19 18:28:28,181 DEBUG   HandlerThread:60959 [handler.py:handle_request():146] handle_request: keepalive
2024-04-19 18:28:33,183 DEBUG   HandlerThread:60959 [handler.py:handle_request():146] handle_request: keepalive
2024-04-19 18:28:38,184 DEBUG   HandlerThread:60959 [handler.py:handle_request():146] handle_request: keepalive
2024-04-19 18:28:43,185 DEBUG   HandlerThread:60959 [handler.py:handle_request():146] handle_request: keepalive
2024-04-19 18:28:48,186 DEBUG   HandlerThread:60959 [handler.py:handle_request():146] handle_request: cancel
2024-04-19 18:28:48,186 DEBUG   HandlerThread:60959 [handler.py:handle_request():146] handle_request: cancel
2024-04-19 18:28:48,187 DEBUG   SenderThread:60959 [sender.py:send():388] Record cancelled: run
2024-04-19 18:28:48,187 DEBUG   HandlerThread:60959 [handler.py:handle_request():146] handle_request: status_report
2024-04-19 18:28:48,787 DEBUG   HandlerThread:60959 [handler.py:handle_request():146] handle_request: shutdown
2024-04-19 18:28:48,787 INFO    HandlerThread:60959 [handler.py:finish():866] shutting down handler
2024-04-19 18:28:49,187 INFO    SenderThread:60959 [sender.py:finish():1546] shutting down sender
2024-04-19 18:28:49,188 INFO    WriterThread:60959 [datastore.py:close():296] close: /home/anushka/Desktop/take_home/task_1/mlops_env/wandb/run-20240419_182718-4zbcv803/run-4zbcv803.wandb
